<?xml version="1.0"?>
<robot name="canopen_robot">
  <link name="base_link"/>
  <link name="joint_1_link"/>
  <link name="joint_2_link"/>
  <link name="joint_3_link"/>
  <link name="joint_4_link"/>
  <link name="joint_5_link"/>
  <link name="joint_6_link"/>

  <joint name="joint_1" type="continuous">
    <parent link="base_link"/>
    <child link="joint_1_link"/>
    <axis xyz="0 0 1"/>
  </joint>

  <joint name="joint_2" type="continuous">
    <parent link="joint_1_link"/>
    <child link="joint_2_link"/>
    <axis xyz="0 0 1"/>
  </joint>

  <joint name="joint_3" type="continuous">
    <parent link="joint_2_link"/>
    <child link="joint_3_link"/>
    <axis xyz="0 0 1"/>
  </joint>

  <joint name="joint_4" type="continuous">
    <parent link="joint_3_link"/>
    <child link="joint_4_link"/>
    <axis xyz="0 0 1"/>
  </joint>

  <joint name="joint_5" type="continuous">
    <parent link="joint_4_link"/>
    <child link="joint_5_link"/>
    <axis xyz="0 0 1"/>
  </joint>

  <joint name="joint_6" type="continuous">
    <parent link="joint_5_link"/>
    <child link="joint_6_link"/>
    <axis xyz="0 0 1"/>
  </joint>
</robot>
