<?xml version="1.0" encoding="utf-8" ?>
<!-- This URDF was automatically created by SolidWorks to URDF Exporter! Originally created by Stephen Brawner (brawner@gmail.com) 
     Commit Version: 1.6.0-4-g7f85cfe  Build Version: 1.6.7995.38578
     For more information, please see http://wiki.ros.org/sw_urdf_exporter -->
<robot name="oldcar111">
    <link name="dummy" />
    <joint name="dummy_joint" type="fixed">
        <parent link="dummy" />
        <child link="base_link" />
    </joint>
    <link name="base_link">
        <inertial>
            <origin xyz="1.9442239403214E-06 0.00531069109650709 0.0238395994341592" rpy="0 0 0" />
            <mass value="0.246843411085798" />
            <inertia ixx="0.000192373271361537" ixy="5.22802381723286E-08" ixz="-1.57229969351522E-09" iyy="0.000335809102347398" iyz="-4.46875478080679E-06" izz="0.000304475372386247" />
        </inertial>
        <visual>
            <origin xyz="0 0 0" rpy="0 0 0" />
            <geometry>
                <mesh filename="package://oldcar111/meshes/base_link.STL" />
            </geometry>
            <material name="">
                <color rgba="0.792156862745098 0.819607843137255 0.933333333333333 1" />
            </material>
        </visual>
        <collision>
            <origin xyz="0 0 0" rpy="0 0 0" />
            <geometry>
                <mesh filename="package://oldcar111/meshes/base_link.STL" />
            </geometry>
        </collision>
    </link>
    <link name="link1">
        <inertial>
            <origin xyz="0.00527799246989458 0.00221512748377152 0.288992598715274" rpy="0 0 0" />
            <mass value="0.400617228197227" />
            <inertia ixx="0.00118928752998524" ixy="-1.66580426187447E-07" ixz="-2.17440480522971E-05" iyy="0.00122553902236228" iyz="-7.86734443364385E-06" izz="0.000207836332848072" />
        </inertial>
        <visual>
            <origin xyz="0 0 0" rpy="0 0 0" />
            <geometry>
                <mesh filename="package://oldcar111/meshes/link1.STL" />
            </geometry>
            <material name="">
                <color rgba="0.698039215686274 0.698039215686274 0.698039215686274 1" />
            </material>
        </visual>
        <collision>
            <origin xyz="0 0 0" rpy="0 0 0" />
            <geometry>
                <mesh filename="package://oldcar111/meshes/link1.STL" />
            </geometry>
        </collision>
    </link>
    <joint name="1" type="revolute">
        <origin xyz="0 -0.00419999972019724 0.054" rpy="-1.5707963267949 0 1.57030745170863" />
        <parent link="base_link" />
        <child link="link1" />
        <axis xyz="-1 0 0" />
        <limit lower="-3.14" upper="0" effort="0" velocity="0" />
    </joint>
    <link name="link2">
        <inertial>
            <origin xyz="-0.0289514418738021 -0.0539893815987094 0.285713893552422" rpy="0 0 0" />
            <mass value="0.230744553272649" />
            <inertia ixx="0.00104956541855008" ixy="1.14186722095414E-07" ixz="-5.64519648302555E-07" iyy="0.00102697475255679" iyz="0.000180581630269562" izz="0.000105441049477574" />
        </inertial>
        <visual>
            <origin xyz="0 0 0" rpy="0 0 0" />
            <geometry>
                <mesh filename="package://oldcar111/meshes/link2.STL" />
            </geometry>
            <material name="">
                <color rgba="0.698039215686274 0.698039215686274 0.698039215686274 1" />
            </material>
        </visual>
        <collision>
            <origin xyz="0 0 0" rpy="0 0 0" />
            <geometry>
                <mesh filename="package://oldcar111/meshes/link2.STL" />
            </geometry>
        </collision>
    </link>
    <joint name="2" type="revolute">
        <origin xyz="-0.0190610592148176 0.0037785921272299 0.492983162251151" rpy="0 0 0" />
        <parent link="link1" />
        <child link="link2" />
        <axis xyz="1 0 0" />
        <limit lower="-2.93" upper="2.95" effort="0" velocity="0" />
    </joint>
    <link name="link3">
        <inertial>
            <origin xyz="0.0817348080152344 0.00631043308468887 0.0145304551130211" rpy="0 0 0" />
            <mass value="0.0824529162671332" />
            <inertia ixx="2.52208026875665E-05" ixy="-9.38918528365317E-07" ixz="-2.15162295674946E-06" iyy="2.61838498056079E-05" iyz="-3.55367452857558E-06" izz="1.95380039083763E-05" />
        </inertial>
        <visual>
            <origin xyz="0 0 0" rpy="0 0 0" />
            <geometry>
                <mesh filename="package://oldcar111/meshes/link3.STL" />
            </geometry>
            <material name="">
                <color rgba="0.698039215686274 0.698039215686274 0.698039215686274 1" />
            </material>
        </visual>
        <collision>
            <origin xyz="0 0 0" rpy="0 0 0" />
            <geometry>
                <mesh filename="package://oldcar111/meshes/link3.STL" />
            </geometry>
        </collision>
    </link>
    <joint name="3" type="continuous">
        <origin xyz="-0.0634554958516763 -0.08466955254996 0.44806252567829" rpy="0 0 0" />
        <parent link="link2" />
        <child link="link3" />
        <axis xyz="-1 0 0" />
    </joint>
    <link name="link4">
        <inertial>
            <origin xyz="0.00890807551218276 0.0130884602175348 0.0817401465685984" rpy="0 0 0" />
            <mass value="0.0824529142602831" />
            <inertia ixx="2.46775716865345E-05" ixy="-4.53665204521974E-06" ixz="-1.32319484330853E-06" iyy="2.10766289984127E-05" iyz="-1.92999691209014E-06" izz="2.5188455562489E-05" />
        </inertial>
        <visual>
            <origin xyz="0 0 0" rpy="0 0 0" />
            <geometry>
                <mesh filename="package://oldcar111/meshes/link4.STL" />
            </geometry>
            <material name="">
                <color rgba="0.698039215686274 0.698039215686274 0.698039215686274 1" />
            </material>
        </visual>
        <collision>
            <origin xyz="0 0 0" rpy="0 0 0" />
            <geometry>
                <mesh filename="package://oldcar111/meshes/link4.STL" />
            </geometry>
        </collision>
    </link>
    <joint name="4" type="continuous">
        <origin xyz="0.0867019191362518 -0.00673445031368503 -0.0154894931182463" rpy="-0.40986791242469 -0.000123856296620052 0" />
        <parent link="link3" />
        <child link="link4" />
        <axis xyz="0 0 -1" />
    </joint>
    <link name="link5">
        <inertial>
            <origin xyz="0.105186720073894 0.00235968914936002 -0.0022246606375701" rpy="0 0 0" />
            <mass value="0.174467238698695" />
            <inertia ixx="0.000154343896810332" ixy="-1.98935759843775E-06" ixz="1.86240133131484E-06" iyy="0.000103856592098492" iyz="-3.22519277835911E-05" izz="9.91083108892448E-05" />
        </inertial>
        <visual>
            <origin xyz="0 0 0" rpy="0 0 0" />
            <geometry>
                <mesh filename="package://oldcar111/meshes/link5.STL" />
            </geometry>
            <material name="">
                <color rgba="1 1 1 1" />
            </material>
        </visual>
        <collision>
            <origin xyz="0 0 0" rpy="0 0 0" />
            <geometry>
                <mesh filename="package://oldcar111/meshes/link5.STL" />
            </geometry>
        </collision>
    </link>
    <joint name="5" type="continuous">
        <origin xyz="-0.00950565079420626 -0.0139732817540251 0.0866999999999829" rpy="1.5703914601342 0 0.973432793021899" />
        <parent link="link4" />
        <child link="link5" />
        <axis xyz="-1 0 0" />
    </joint>
    <link name="linkzhua1">
        <inertial>
            <origin xyz="-0.00450736179791811 -0.000673663938952296 0.00380318250475943" rpy="0 0 0" />
            <mass value="0.0276498547531941" />
            <inertia ixx="6.62112429571255E-06" ixy="1.23049107146354E-07" ixz="5.68457369224247E-07" iyy="7.500189084869E-06" iyz="-1.12447985360647E-06" izz="7.54576526882826E-06" />
        </inertial>
        <visual>
            <origin xyz="0 0 0" rpy="0 0 0" />
            <geometry>
                <mesh filename="package://oldcar111/meshes/linkzhua1.STL" />
            </geometry>
            <material name="">
                <color rgba="1 1 1 1" />
            </material>
        </visual>
        <collision>
            <origin xyz="0 0 0" rpy="0 0 0" />
            <geometry>
                <mesh filename="package://oldcar111/meshes/linkzhua1.STL" />
            </geometry>
        </collision>
    </link>
    <joint name="zhua1" type="prismatic">
        <origin xyz="0.155699999999986 0.00826760283319106 0.00912539690176883" rpy="2.27424838462147 -0.821045734463187 1.57079632679491" />
        <parent link="link5" />
        <child link="linkzhua1" />
        <axis xyz="-1 0 0" />
        <limit lower="-0.06" upper="0" effort="0" velocity="0" />
    </joint>
    <link name="linkzhua2">
        <inertial>
            <origin xyz="0.00123526659265605 0.00575362909473481 -0.000479857152509387" rpy="0 0 0" />
            <mass value="0.0276496025259502" />
            <inertia ixx="7.69978326990058E-06" ixy="-8.08090839029367E-07" ixz="4.82144588161451E-07" iyy="6.78857023532845E-06" iyz="-8.83092307840954E-07" izz="7.17860180138716E-06" />
        </inertial>
        <visual>
            <origin xyz="0 0 0" rpy="0 0 0" />
            <geometry>
                <mesh filename="package://oldcar111/meshes/linkzhua2.STL" />
            </geometry>
            <material name="">
                <color rgba="1 1 1 1" />
            </material>
        </visual>
        <collision>
            <origin xyz="0 0 0" rpy="0 0 0" />
            <geometry>
                <mesh filename="package://oldcar111/meshes/linkzhua2.STL" />
            </geometry>
        </collision>
    </link>
    <joint name="zhua2" type="prismatic">
        <origin xyz="0.155700001466271 -0.00839043372952131 -0.00901101641300339" rpy="2.12843991961849 -0.226127160063763 1.91590207174177" />
        <parent link="link5" />
        <child link="linkzhua2" />
        <axis xyz="0.789038133883824 0.605176450061446 -0.105736878940877" />
        <limit lower="-0.06" upper="0" effort="0" velocity="0" />
    </joint>
    <transmission name="trans_1">
        <type>transmission_interface/SimpleTransmission</type>
        <joint name="1">
            <hardwareInterface>hardware_interface/EffortJointInterface</hardwareInterface>
        </joint>
        <actuator name="1_motor">
            <hardwareInterface>hardware_interface/EffortJointInterface</hardwareInterface>
            <mechanicalReduction>1</mechanicalReduction>
        </actuator>
    </transmission>
    <transmission name="trans_2">
        <type>transmission_interface/SimpleTransmission</type>
        <joint name="2">
            <hardwareInterface>hardware_interface/EffortJointInterface</hardwareInterface>
        </joint>
        <actuator name="2_motor">
            <hardwareInterface>hardware_interface/EffortJointInterface</hardwareInterface>
            <mechanicalReduction>1</mechanicalReduction>
        </actuator>
    </transmission>
    <transmission name="trans_3">
        <type>transmission_interface/SimpleTransmission</type>
        <joint name="3">
            <hardwareInterface>hardware_interface/EffortJointInterface</hardwareInterface>
        </joint>
        <actuator name="3_motor">
            <hardwareInterface>hardware_interface/EffortJointInterface</hardwareInterface>
            <mechanicalReduction>1</mechanicalReduction>
        </actuator>
    </transmission>
    <transmission name="trans_4">
        <type>transmission_interface/SimpleTransmission</type>
        <joint name="4">
            <hardwareInterface>hardware_interface/EffortJointInterface</hardwareInterface>
        </joint>
        <actuator name="4_motor">
            <hardwareInterface>hardware_interface/EffortJointInterface</hardwareInterface>
            <mechanicalReduction>1</mechanicalReduction>
        </actuator>
    </transmission>
    <transmission name="trans_5">
        <type>transmission_interface/SimpleTransmission</type>
        <joint name="5">
            <hardwareInterface>hardware_interface/EffortJointInterface</hardwareInterface>
        </joint>
        <actuator name="5_motor">
            <hardwareInterface>hardware_interface/EffortJointInterface</hardwareInterface>
            <mechanicalReduction>1</mechanicalReduction>
        </actuator>
    </transmission>
    <transmission name="trans_zhua1">
        <type>transmission_interface/SimpleTransmission</type>
        <joint name="zhua1">
            <hardwareInterface>hardware_interface/EffortJointInterface</hardwareInterface>
        </joint>
        <actuator name="zhua1_motor">
            <hardwareInterface>hardware_interface/EffortJointInterface</hardwareInterface>
            <mechanicalReduction>1</mechanicalReduction>
        </actuator>
    </transmission>
    <transmission name="trans_zhua2">
        <type>transmission_interface/SimpleTransmission</type>
        <joint name="zhua2">
            <hardwareInterface>hardware_interface/EffortJointInterface</hardwareInterface>
        </joint>
        <actuator name="zhua2_motor">
            <hardwareInterface>hardware_interface/EffortJointInterface</hardwareInterface>
            <mechanicalReduction>1</mechanicalReduction>
        </actuator>
    </transmission>
    <gazebo>
        <plugin name="gazebo_ros_control" filename="libgazebo_ros_control.so">
            <robotNamespace>/</robotNamespace>
        </plugin>
    </gazebo>
</robot>

