<?xml version="1.0" encoding="utf-8"?>
<!-- This URDF was automatically created by SolidWorks to URDF Exporter! Originally created by Stephen Brawner (brawner@gmail.com) 
     Commit Version: 1.6.0-4-g7f85cfe  Build Version: 1.6.7995.38578
     For more information, please see http://wiki.ros.org/sw_urdf_exporter -->
<robot
  name="car_urdf">
  <link
    name="base_link">
    <inertial>
      <origin
        xyz="-0.00722672875113273 -0.000104719885171668 0.0735986679476475"
        rpy="0 0 0" />
      <mass
        value="18.2147755600028" />
      <inertia
        ixx="0.0356811351637386"
        ixy="-3.30703632254708E-06"
        ixz="1.7314058145905E-05"
        iyy="0.0605687964397314"
        iyz="-6.6672149024295E-06"
        izz="0.0785360308707173" />
    </inertial>
    <visual>
      <origin
        xyz="0 0 0"
        rpy="0 0 0" />
      <geometry>
        <mesh
          filename="package://car_urdf/meshes/base_link.STL" />
      </geometry>
      <material
        name="">
        <color
          rgba="0.298039215686275 0.298039215686275 0.298039215686275 1" />
      </material>
    </visual>
    <collision>
      <origin
        xyz="0 0 0"
        rpy="0 0 0" />
      <geometry>
        <mesh
          filename="package://car_urdf/meshes/base_link.STL" />
      </geometry>
    </collision>
  </link>
  <link
    name="left_ahead_wheel">
    <inertial>
      <origin
        xyz="0 0.000176599813181244 0"
        rpy="0 0 0" />
      <mass
        value="0.0487751853603894" />
      <inertia
        ixx="1.19431136820125E-05"
        ixy="-6.24890945618571E-20"
        ixz="1.41367905477624E-08"
        iyy="2.10139464635948E-05"
        iyz="1.02886996373743E-21"
        izz="1.22459599088019E-05" />
    </inertial>
    <visual>
      <origin
        xyz="0 0 0"
        rpy="0 0 0" />
      <geometry>
        <mesh
          filename="package://car_urdf/meshes/left_ahead_wheel.STL" />
      </geometry>
      <material
        name="">
        <color
          rgba="1 1 1 1" />
      </material>
    </visual>
    <collision>
      <origin
        xyz="0 0 0"
        rpy="0 0 0" />
      <geometry>
        <mesh
          filename="package://car_urdf/meshes/left_ahead_wheel.STL" />
      </geometry>
    </collision>
  </link>
  <joint
    name="left_ahead_wheel_joint"
    type="continuous">
    <origin
      xyz="-0.155999999999997 -0.219000195879134 0"
      rpy="0 0 0" />
    <parent
      link="base_link" />
    <child
      link="left_ahead_wheel" />
    <axis
      xyz="0 1 0" />
  </joint>
  <link
    name="left_back_wheel">
    <inertial>
      <origin
        xyz="5.55111512312578E-17 0.0001765998131813 0"
        rpy="0 0 0" />
      <mass
        value="0.0487751853603894" />
      <inertia
        ixx="1.19453151301021E-05"
        ixy="-6.37807671524902E-20"
        ixz="2.9354773388473E-08"
        iyy="2.10139464635948E-05"
        iyz="-1.07324804301432E-22"
        izz="1.22437584607124E-05" />
    </inertial>
    <visual>
      <origin
        xyz="0 0 0"
        rpy="0 0 0" />
      <geometry>
        <mesh
          filename="package://car_urdf/meshes/left_back_wheel.STL" />
      </geometry>
      <material
        name="">
        <color
          rgba="1 1 1 1" />
      </material>
    </visual>
    <collision>
      <origin
        xyz="0 0 0"
        rpy="0 0 0" />
      <geometry>
        <mesh
          filename="package://car_urdf/meshes/left_back_wheel.STL" />
      </geometry>
    </collision>
  </link>
  <joint
    name="left_back_wheel_joint"
    type="continuous">
    <origin
      xyz="0.156000000000004 -0.219000195879131 0"
      rpy="0 0 0" />
    <parent
      link="base_link" />
    <child
      link="left_back_wheel" />
    <axis
      xyz="0 1 0" />
  </joint>
  <link
    name="right_ahead_wheel">
    <inertial>
      <origin
        xyz="0 -0.000176599813181272 1.73472347597681E-18"
        rpy="0 0 0" />
      <mass
        value="0.0487751853603893" />
      <inertia
        ixx="1.19431136820125E-05"
        ixy="6.25659507956832E-20"
        ixz="1.41367905477636E-08"
        iyy="2.10139464635948E-05"
        iyz="6.6508695313557E-22"
        izz="1.22459599088019E-05" />
    </inertial>
    <visual>
      <origin
        xyz="0 0 0"
        rpy="0 0 0" />
      <geometry>
        <mesh
          filename="package://car_urdf/meshes/right_ahead_wheel.STL" />
      </geometry>
      <material
        name="">
        <color
          rgba="1 1 1 1" />
      </material>
    </visual>
    <collision>
      <origin
        xyz="0 0 0"
        rpy="0 0 0" />
      <geometry>
        <mesh
          filename="package://car_urdf/meshes/right_ahead_wheel.STL" />
      </geometry>
    </collision>
  </link>
  <joint
    name="right_ahead_wheel_joint"
    type="continuous">
    <origin
      xyz="-0.155999999999997 0.219000195879134 0"
      rpy="0 0 0" />
    <parent
      link="base_link" />
    <child
      link="right_ahead_wheel" />
    <axis
      xyz="0 1 0" />
  </joint>
  <link
    name="right_back_wheel">
    <inertial>
      <origin
        xyz="0 -0.000176599813181272 0"
        rpy="0 0 0" />
      <mass
        value="0.0487751853603893" />
      <inertia
        ixx="1.1945315130102E-05"
        ixy="6.30303659563342E-20"
        ixz="2.93547733881655E-08"
        iyy="2.10139464635948E-05"
        iyz="1.14546139079296E-22"
        izz="1.22437584607124E-05" />
    </inertial>
    <visual>
      <origin
        xyz="0 0 0"
        rpy="0 0 0" />
      <geometry>
        <mesh
          filename="package://car_urdf/meshes/right_back_wheel.STL" />
      </geometry>
      <material
        name="">
        <color
          rgba="1 1 1 1" />
      </material>
    </visual>
    <collision>
      <origin
        xyz="0 0 0"
        rpy="0 0 0" />
      <geometry>
        <mesh
          filename="package://car_urdf/meshes/right_back_wheel.STL" />
      </geometry>
    </collision>
  </link>
  <joint
    name="right_back_wheel_joint"
    type="continuous">
    <origin
      xyz="0.156000000000004 0.219000195879132 0"
      rpy="0 0 0" />
    <parent
      link="base_link" />
    <child
      link="right_back_wheel" />
    <axis
      xyz="0 1 0" />
  </joint>
  <link
    name="left_ahead_arm">
    <inertial>
      <origin
        xyz="8.51004323815241E-08 0.00550753511779323 0.166867745732428"
        rpy="0 0 0" />
      <mass
        value="1.58786786548102" />
      <inertia
        ixx="0.0101203073694155"
        ixy="-2.47348255244641E-12"
        ixz="6.4665669213483E-09"
        iyy="0.0114564870751773"
        iyz="-8.66733028932378E-08"
        izz="0.00151495709722869" />
    </inertial>
    <visual>
      <origin
        xyz="0 0 0"
        rpy="0 0 0" />
      <geometry>
        <mesh
          filename="package://car_urdf/meshes/left_ahead_arm.STL" />
      </geometry>
      <material
        name="">
        <color
          rgba="0.752941176470588 0.752941176470588 0.752941176470588 1" />
      </material>
    </visual>
    <collision>
      <origin
        xyz="0 0 0"
        rpy="0 0 0" />
      <geometry>
        <mesh
          filename="package://car_urdf/meshes/left_ahead_arm.STL" />
      </geometry>
    </collision>
  </link>
  <joint
    name="left_ahead_arm_joint"
    type="revolute">
    <origin
      xyz="-0.277600000000002 -0.241000195879134 0.0551000000000096"
      rpy="0 0 0" />
    <parent
      link="base_link" />
    <child
      link="left_ahead_arm" />
    <axis
      xyz="0 1 0" />
    <!-- LIMIT: edit lower/upper/effort/velocity here -->
    <limit
      lower="-3.665"
      upper="0.524"
      effort="50"
      velocity="1.57" />
  </joint>
  <link
    name="left_back_arm">
    <inertial>
      <origin
        xyz="8.51004336999139E-08 0.00550753511779284 0.166867745732428"
        rpy="0 0 0" />
      <mass
        value="1.58786786548102" />
      <inertia
        ixx="0.0101203073694154"
        ixy="-2.47348286009605E-12"
        ixz="6.46656686108232E-09"
        iyy="0.0114564870751773"
        iyz="-8.66733026505326E-08"
        izz="0.00151495709722865" />
    </inertial>
    <visual>
      <origin
        xyz="0 0 0"
        rpy="0 0 0" />
      <geometry>
        <mesh
          filename="package://car_urdf/meshes/left_back_arm.STL" />
      </geometry>
      <material
        name="">
        <color
          rgba="0.752941176470588 0.752941176470588 0.752941176470588 1" />
      </material>
    </visual>
    <collision>
      <origin
        xyz="0 0 0"
        rpy="0 0 0" />
      <geometry>
        <mesh
          filename="package://car_urdf/meshes/left_back_arm.STL" />
      </geometry>
    </collision>
  </link>
  <joint
    name="left_back_arm_joint"
    type="revolute">
    <origin
      xyz="0.277599999999999 -0.241000195879128 0.0551000000000025"
      rpy="0 0 0" />
    <parent
      link="base_link" />
    <child
      link="left_back_arm" />
    <axis
      xyz="0 1 0" />
    <!-- LIMIT: edit lower/upper/effort/velocity here -->
    <limit
      lower="-0.524"
      upper="3.665"
      effort="50"
      velocity="1.57" />
  </joint>
  <link
    name="right_ahead_arm">
    <inertial>
      <origin
        xyz="-8.51007762522893E-08 -0.00550753511778782 0.166867745732428"
        rpy="0 0 0" />
      <mass
        value="1.58786786548102" />
      <inertia
        ixx="0.0101203073694157"
        ixy="-2.47348335347705E-12"
        ixz="-6.46654918706048E-09"
        iyy="0.0114564870751773"
        iyz="8.66733026516659E-08"
        izz="0.0015149570972289" />
    </inertial>
    <visual>
      <origin
        xyz="0 0 0"
        rpy="0 0 0" />
      <geometry>
        <mesh
          filename="package://car_urdf/meshes/right_ahead_arm.STL" />
      </geometry>
      <material
        name="">
        <color
          rgba="0.752941176470588 0.752941176470588 0.752941176470588 1" />
      </material>
    </visual>
    <collision>
      <origin
        xyz="0 0 0"
        rpy="0 0 0" />
      <geometry>
        <mesh
          filename="package://car_urdf/meshes/right_ahead_arm.STL" />
      </geometry>
    </collision>
  </link>
  <joint
    name="right_ahead_arm_joint"
    type="revolute">
    <origin
      xyz="-0.277600000000005 0.24100019587914 0.0551000000000029"
      rpy="0 0 0" />
    <parent
      link="base_link" />
    <child
      link="right_ahead_arm" />
    <axis
      xyz="0 1 0" />
    <!-- LIMIT: edit lower/upper/effort/velocity here -->
    <limit
      lower="-3.665"
      upper="0.524"
      effort="50"
      velocity="1.57" />
  </joint>
  <link
    name="right_back_arm">
    <inertial>
      <origin
        xyz="-8.51007770918955E-08 -0.00550753511778787 0.166867745732428"
        rpy="0 0 0" />
      <mass
        value="1.58786786548102" />
      <inertia
        ixx="0.0101203073694157"
        ixy="-2.47348332013965E-12"
        ixz="-6.46654912689874E-09"
        iyy="0.0114564870751773"
        iyz="8.66733026512717E-08"
        izz="0.0015149570972289" />
    </inertial>
    <visual>
      <origin
        xyz="0 0 0"
        rpy="0 0 0" />
      <geometry>
        <mesh
          filename="package://car_urdf/meshes/right_back_arm.STL" />
      </geometry>
      <material
        name="">
        <color
          rgba="0.752941176470588 0.752941176470588 0.752941176470588 1" />
      </material>
    </visual>
    <collision>
      <origin
        xyz="0 0 0"
        rpy="0 0 0" />
      <geometry>
        <mesh
          filename="package://car_urdf/meshes/right_back_arm.STL" />
      </geometry>
    </collision>
  </link>
  <joint
    name="right_back_arm_joint"
    type="revolute">
    <origin
      xyz="0.277599999999996 0.241000195879143 0.0551000000000005"
      rpy="0 0 0" />
    <parent
      link="base_link" />
    <child
      link="right_back_arm" />
    <axis
      xyz="0 1 0" />
    <!-- LIMIT: edit lower/upper/effort/velocity here -->
    <limit
      lower="-0.524"
      upper="3.665"
      effort="50"
      velocity="1.57" />
  </joint>
  <link
    name="big_course_part">
    <inertial>
      <origin
        xyz="-3.8909100036344E-07 -0.000840655594497267 -0.000626755979201393"
        rpy="0 0 0" />
      <mass
        value="4.058247002138" />
      <inertia
        ixx="0.00215393279764294"
        ixy="7.58591199427245E-08"
        ixz="3.93372022302556E-08"
        iyy="0.00241219360465986"
        iyz="-2.17404141773458E-07"
        izz="0.00317731381306234" />
    </inertial>
    <visual>
      <origin
        xyz="0 0 0"
        rpy="0 0 0" />
      <geometry>
        <mesh
          filename="package://car_urdf/meshes/big_course_part.STL" />
      </geometry>
      <material
        name="">
        <color
          rgba="0.898039215686275 0.917647058823529 0.929411764705882 1" />
      </material>
    </visual>
    <collision>
      <origin
        xyz="0 0 0"
        rpy="0 0 0" />
      <geometry>
        <mesh
          filename="package://car_urdf/meshes/big_course_part.STL" />
      </geometry>
    </collision>
  </link>
  <joint
    name="big_course_joint"
    type="revolute">
    <origin
      xyz="0.120249999999999 -0.00100019587899608 0.199849999999992"
      rpy="0 0 0" />
    <parent
      link="base_link" />
    <child
      link="big_course_part" />
    <axis
      xyz="0 0 1" />
    <!-- LIMIT: edit lower/upper/effort/velocity here -->
    <limit
      lower="-2.356"
      upper="2.356"
      effort="66"
      velocity="1.57" />
  </joint>
  <link
    name="big_pitch_part">
    <inertial>
      <origin
        xyz="0.0006884362389879 -0.00351787295254652 0.273450135960469"
        rpy="0 0 0" />
      <mass
        value="1.11922784486201" />
      <inertia
        ixx="0.00568894059773443"
        ixy="-1.3652715795107E-07"
        ixz="-4.73588926530147E-07"
        iyy="0.00572908953794008"
        iyz="-2.99304417500471E-07"
        izz="0.000293741782906926" />
    </inertial>
    <visual>
      <origin
        xyz="0 0 0"
        rpy="0 0 0" />
      <geometry>
        <mesh
          filename="package://car_urdf/meshes/big_pitch_part.STL" />
      </geometry>
      <material
        name="">
        <color
          rgba="0.898039215686275 0.917647058823529 0.929411764705882 1" />
      </material>
    </visual>
    <collision>
      <origin
        xyz="0 0 0"
        rpy="0 0 0" />
      <geometry>
        <mesh
          filename="package://car_urdf/meshes/big_pitch_part.STL" />
      </geometry>
    </collision>
  </link>
  <joint
    name="big_pitch_joint"
    type="revolute">
    <origin
      xyz="0 0.00320000000000144 0.0614876897975586"
      rpy="0 0 0" />
    <parent
      link="big_course_part" />
    <child
      link="big_pitch_part" />
    <axis
      xyz="0 1 0" />
    <!-- LIMIT: edit lower/upper/effort/velocity here -->
    <limit
      lower="-0.960"
      upper="1.571"
      effort="66"
      velocity="1.57" />
  </joint>
  <link
    name="small_pitch_part">
    <inertial>
      <origin
        xyz="-0.000478562561521789 0.00702848851035885 0.161325810486218"
        rpy="0 0 0" />
      <mass
        value="1.16129891011757" />
      <inertia
        ixx="0.00249381888344274"
        ixy="1.73782848553545E-07"
        ixz="1.50375460740508E-08"
        iyy="0.00212433704863666"
        iyz="-4.69965810105997E-06"
        izz="0.000707884980998509" />
    </inertial>
    <visual>
      <origin
        xyz="0 0 0"
        rpy="0 0 0" />
      <geometry>
        <mesh
          filename="package://car_urdf/meshes/small_pitch_part.STL" />
      </geometry>
      <material
        name="">
        <color
          rgba="0.898039215686275 0.917647058823529 0.929411764705882 1" />
      </material>
    </visual>
    <collision>
      <origin
        xyz="0 0 0"
        rpy="0 0 0" />
      <geometry>
        <mesh
          filename="package://car_urdf/meshes/small_pitch_part.STL" />
      </geometry>
    </collision>
  </link>
  <joint
    name="small_pitch_joint"
    type="revolute">
    <origin
      xyz="0 -0.00980000000004102 0.515300000000048"
      rpy="0 0 0" />
    <parent
      link="big_pitch_part" />
    <child
      link="small_pitch_part" />
    <axis
      xyz="0 1 0" />
    <!-- LIMIT: edit lower/upper/effort/velocity here -->
    <limit
      lower="-1.0"
      upper="2.793"
      effort="18"
      velocity="1.57" />
  </joint>
  <link
    name="hands_pitch_part">
    <inertial>
      <origin
        xyz="-0.011121182958557 0.0245556141058408 7.49702639968319E-08"
        rpy="0 0 0" />
      <mass
        value="0.198490718521714" />
      <inertia
        ixx="3.96854415731618E-05"
        ixy="2.25690275527628E-06"
        ixz="-4.05948875669033E-10"
        iyy="6.48873453550081E-05"
        iyz="-3.93944365084045E-07"
        izz="6.68874608279779E-05" />
    </inertial>
    <visual>
      <origin
        xyz="0 0 0"
        rpy="0 0 0" />
      <geometry>
        <mesh
          filename="package://car_urdf/meshes/hands_pitch_part.STL" />
      </geometry>
      <material
        name="">
        <color
          rgba="0.898039215686275 0.917647058823529 0.929411764705882 1" />
      </material>
    </visual>
    <collision>
      <origin
        xyz="0 0 0"
        rpy="0 0 0" />
      <geometry>
        <mesh
          filename="package://car_urdf/meshes/hands_pitch_part.STL" />
      </geometry>
    </collision>
  </link>
  <joint
    name="hands_pitch_joint"
    type="revolute">
    <origin
      xyz="0 0.0450999999999989 0.435999999999992"
      rpy="0 0 0" />
    <parent
      link="small_pitch_part" />
    <child
      link="hands_pitch_part" />
    <axis
      xyz="0 1 0" />
    <!-- LIMIT: edit lower/upper/effort/velocity here -->
    <limit
      lower="-1.57"
      upper="2.356"
      effort="6"
      velocity="1.57" />
  </joint>
  <link
    name="hands_roll_part">
    <inertial>
      <origin
        xyz="-0.0236906632209934 7.25738848010582E-08 0.0112273224435504"
        rpy="0 0 0" />
      <mass
        value="0.20602863354353" />
      <inertia
        ixx="6.90541665876816E-05"
        ixy="-3.95703419621262E-07"
        ixz="2.8621007927603E-06"
        iyy="7.03217179878434E-05"
        iyz="4.07501680272324E-10"
        izz="4.11534286606825E-05" />
    </inertial>
    <visual>
      <origin
        xyz="0 0 0"
        rpy="0 0 0" />
      <geometry>
        <mesh
          filename="package://car_urdf/meshes/hands_roll_part.STL" />
      </geometry>
      <material
        name="">
        <color
          rgba="0.898039215686275 0.917647058823529 0.929411764705882 1" />
      </material>
    </visual>
    <collision>
      <origin
        xyz="0 0 0"
        rpy="0 0 0" />
      <geometry>
        <mesh
          filename="package://car_urdf/meshes/hands_roll_part.STL" />
      </geometry>
    </collision>
  </link>
  <joint
    name="hands_roll_joint"
    type="revolute">
    <origin
      xyz="-0.0494999999999985 0.0265000000000013 0"
      rpy="0 0 0" />
    <parent
      link="hands_pitch_part" />
    <child
      link="hands_roll_part" />
    <axis
      xyz="-1 0 0" />
    <!-- LIMIT: edit lower/upper/effort/velocity here -->
    <limit
      lower="-2.356"
      upper="2.356"
      effort="6"
      velocity="1.57" />
  </joint>
  <link
    name="handshands_course_part">
    <inertial>
      <origin
        xyz="-0.00244986441444667 1.52714053028493E-05 0.0657380508982133"
        rpy="0 0 0" />
      <mass
        value="0.229769688817791" />
      <inertia
        ixx="0.000151079549752767"
        ixy="6.18390681024649E-07"
        ixz="2.72507755517067E-06"
        iyy="8.23862749021681E-05"
        iyz="-7.35002424759208E-09"
        izz="0.000167178569432664" />
    </inertial>
    <visual>
      <origin
        xyz="0 0 0"
        rpy="0 0 0" />
      <geometry>
        <mesh
          filename="package://car_urdf/meshes/handshands_course_part.STL" />
      </geometry>
      <material
        name="">
        <color
          rgba="1 1 1 1" />
      </material>
    </visual>
    <collision>
      <origin
        xyz="0 0 0"
        rpy="0 0 0" />
      <geometry>
        <mesh
          filename="package://car_urdf/meshes/handshands_course_part.STL" />
      </geometry>
    </collision>
  </link>
  <joint
    name="hands_course_joint"
    type="revolute">
    <origin
      xyz="-0.0265000000000413 0 0.0424999999999722"
      rpy="0 0 0" />
    <parent
      link="hands_roll_part" />
    <child
      link="handshands_course_part" />
    <axis
      xyz="0 0 1" />
    <!-- LIMIT: edit lower/upper/effort/velocity here -->
    <limit
      lower="-7.069"
      upper="7.069"
      effort="6"
      velocity="1.57" />
  </joint>
  <link
    name="catch_camera">
    <inertial>
      <origin
        xyz="-0.00397693184444656 -0.000923469734682813 -0.0106782498598019"
        rpy="0 0 0" />
      <mass
        value="1.07678794206715" />
      <inertia
        ixx="0.000209400343015507"
        ixy="-1.32038119143981E-07"
        ixz="3.317646085273E-05"
        iyy="0.000197188399368552"
        iyz="-3.95621659167232E-07"
        izz="0.000289399291245458" />
    </inertial>
    <visual>
      <origin
        xyz="0 0 0"
        rpy="0 0 0" />
      <geometry>
        <mesh
          filename="package://car_urdf/meshes/catch_camera.STL" />
      </geometry>
      <material
        name="">
        <color
          rgba="1 0.941176470588235 0.67843137254902 1" />
      </material>
    </visual>
    <collision>
      <origin
        xyz="0 0 0"
        rpy="0 0 0" />
      <geometry>
        <mesh
          filename="package://car_urdf/meshes/catch_camera.STL" />
      </geometry>
    </collision>
  </link>
  <joint
    name="catch_camera"
    type="revolute">
    <origin
      xyz="-0.0462233943895681 0.00134448857148927 0.0777106538096684"
      rpy="0 0 0" />
    <parent
      link="handshands_course_part" />
    <child
      link="catch_camera" />
    <axis
      xyz="-0.342020143325663 0 -0.939692620785911" />
    <!-- LIMIT: edit lower/upper/effort/velocity here -->
    <limit
      lower="0"
      upper="0"
      effort="0"
      velocity="0" />
  </joint>
  <link
    name="lidar">
    <inertial>
      <origin
        xyz="1.62370117351429E-15 -3.33066907387547E-16 -4.44089209850063E-16"
        rpy="0 0 0" />
      <mass
        value="0.742920987579563" />
      <inertia
        ixx="0.000937798449134027"
        ixy="1.03077101557214E-34"
        ixz="-4.61708918612271E-19"
        iyy="0.000937798449134027"
        iyz="-2.78475796235466E-20"
        izz="0.0010632127983498" />
    </inertial>
    <visual>
      <origin
        xyz="0 0 0"
        rpy="0 0 0" />
      <geometry>
        <mesh
          filename="package://car_urdf/meshes/lidar.STL" />
      </geometry>
      <material
        name="">
        <color
          rgba="1 1 1 1" />
      </material>
    </visual>
    <collision>
      <origin
        xyz="0 0 0"
        rpy="0 0 0" />
      <geometry>
        <mesh
          filename="package://car_urdf/meshes/lidar.STL" />
      </geometry>
    </collision>
  </link>
  <joint
    name="lidar_joint"
    type="fixed">
    <origin
      xyz="-0.1555 0.00100019587913144 0.300699999999992"
      rpy="0 0 0" />
    <parent
      link="base_link" />
    <child
      link="lidar" />
    <axis
      xyz="0 0 0" />
  </joint>
  <link
    name="camera">
    <inertial>
      <origin
        xyz="0.00422507049806125 -0.00323775103650951 -0.0020973604251604"
        rpy="0 0 0" />
      <mass
        value="0.0491654266514404" />
      <inertia
        ixx="2.79392843654149E-05"
        ixy="-4.34509658882139E-07"
        ixz="-7.70024903303203E-09"
        iyy="3.41762421577894E-06"
        iyz="-2.15842945491109E-09"
        izz="2.71851885152033E-05" />
    </inertial>
    <visual>
      <origin
        xyz="0 0 0"
        rpy="0 0 0" />
      <geometry>
        <mesh
          filename="package://car_urdf/meshes/camera.STL" />
      </geometry>
      <material
        name="">
        <color
          rgba="1 1 1 1" />
      </material>
    </visual>
    <collision>
      <origin
        xyz="0 0 0"
        rpy="0 0 0" />
      <geometry>
        <mesh
          filename="package://car_urdf/meshes/camera.STL" />
      </geometry>
    </collision>
  </link>
  <joint
    name="camera_joint"
    type="fixed">
    <origin
      xyz="-0.254895203624053 0.00376119017118452 0.228826235475407"
      rpy="0 0 0" />
    <parent
      link="base_link" />
    <child
      link="camera" />
    <axis
      xyz="0 0 0" />
  </joint>
</robot>
