<?xml version="1.0" encoding="utf-8"?>
<!-- This URDF was automatically created by SolidWorks to URDF Exporter! Originally created by Stephen Brawner (brawner@gmail.com) 
     Commit Version: 1.6.0-4-g7f85cfe  Build Version: 1.6.7995.38578
     For more information, please see http://wiki.ros.org/sw_urdf_exporter -->
<robot
  name="car_total">
  <link
    name="base_link">
    <inertial>
      <origin
        xyz="0.0072267287511327 0.000104719885171675 0.0735986679476476"
        rpy="0 0 0" />
      <mass
        value="18.2147755600028" />
      <inertia
        ixx="0.0356811351637089"
        ixy="-3.30703606727026E-06"
        ixz="-1.73140581507929E-05"
        iyy="0.060568796439748"
        iyz="6.66721495900119E-06"
        izz="0.0785360308707043" />
    </inertial>
    <visual>
      <origin
        xyz="0 0 0"
        rpy="0 0 0" />
      <geometry>
        <mesh
          filename="package://car_total/meshes/base_link.STL" />
      </geometry>
      <material
        name="">
        <color
          rgba="0.298039215686275 0.298039215686275 0.298039215686275 1" />
      </material>
    </visual>
    <collision>
      <origin
        xyz="0 0 0"
        rpy="0 0 0" />
      <geometry>
        <mesh
          filename="package://car_total/meshes/base_link.STL" />
      </geometry>
    </collision>
  </link>
  <link
    name="left_ahead_wheel">
    <inertial>
      <origin
        xyz="0 -0.000176599813181244 0"
        rpy="0 0 0" />
      <mass
        value="0.0487751853603894" />
      <inertia
        ixx="1.19431136820125E-05"
        ixy="-6.24893308559522E-20"
        ixz="-1.41367905477624E-08"
        iyy="2.10139464635948E-05"
        iyz="-1.02755228259716E-21"
        izz="1.22459599088019E-05" />
    </inertial>
    <visual>
      <origin
        xyz="0 0 0"
        rpy="0 0 0" />
      <geometry>
        <mesh
          filename="package://car_total/meshes/left_ahead_wheel.STL" />
      </geometry>
      <material
        name="">
        <color
          rgba="1 1 1 1" />
      </material>
    </visual>
    <collision>
      <origin
        xyz="0 0 0"
        rpy="0 0 0" />
      <geometry>
        <mesh
          filename="package://car_total/meshes/left_ahead_wheel.STL" />
      </geometry>
    </collision>
  </link>
  <joint
    name="left_ahead_wheel_joint"
    type="continuous">
    <origin
      xyz="0.155999999999997 0.219000195879134 0"
      rpy="0 0 0" />
    <parent
      link="base_link" />
    <child
      link="left_ahead_wheel" />
    <axis
      xyz="0 -1 0" />
  </joint>
  <link
    name="left_back_wheel">
    <inertial>
      <origin
        xyz="-5.55111512312578E-17 -0.0001765998131813 0"
        rpy="0 0 0" />
      <mass
        value="0.0487751853603894" />
      <inertia
        ixx="1.19453151301021E-05"
        ixy="-6.37807671524902E-20"
        ixz="-2.9354773388473E-08"
        iyy="2.10139464635948E-05"
        iyz="1.07324804301432E-22"
        izz="1.22437584607124E-05" />
    </inertial>
    <visual>
      <origin
        xyz="0 0 0"
        rpy="0 0 0" />
      <geometry>
        <mesh
          filename="package://car_total/meshes/left_back_wheel.STL" />
      </geometry>
      <material
        name="">
        <color
          rgba="1 1 1 1" />
      </material>
    </visual>
    <collision>
      <origin
        xyz="0 0 0"
        rpy="0 0 0" />
      <geometry>
        <mesh
          filename="package://car_total/meshes/left_back_wheel.STL" />
      </geometry>
    </collision>
  </link>
  <joint
    name="left_back_wheel_joint"
    type="continuous">
    <origin
      xyz="-0.156000000000004 0.219000195879131 0"
      rpy="0 0 0" />
    <parent
      link="base_link" />
    <child
      link="left_back_wheel" />
    <axis
      xyz="0 -1 0" />
  </joint>
  <link
    name="right_ahead_wheel">
    <inertial>
      <origin
        xyz="0 0.000176599813181272 1.73472347597681E-18"
        rpy="0 0 0" />
      <mass
        value="0.0487751853603893" />
      <inertia
        ixx="1.19431136820125E-05"
        ixy="6.25653898895604E-20"
        ixz="-1.41367905477636E-08"
        iyy="2.10139464635948E-05"
        iyz="-6.66376836206928E-22"
        izz="1.22459599088019E-05" />
    </inertial>
    <visual>
      <origin
        xyz="0 0 0"
        rpy="0 0 0" />
      <geometry>
        <mesh
          filename="package://car_total/meshes/right_ahead_wheel.STL" />
      </geometry>
      <material
        name="">
        <color
          rgba="1 1 1 1" />
      </material>
    </visual>
    <collision>
      <origin
        xyz="0 0 0"
        rpy="0 0 0" />
      <geometry>
        <mesh
          filename="package://car_total/meshes/right_ahead_wheel.STL" />
      </geometry>
    </collision>
  </link>
  <joint
    name="right_ahead_wheel_joint"
    type="continuous">
    <origin
      xyz="0.155999999999997 -0.219000195879134 0"
      rpy="0 0 0" />
    <parent
      link="base_link" />
    <child
      link="right_ahead_wheel" />
    <axis
      xyz="0 -1 0" />
  </joint>
  <link
    name="right_back_wheel">
    <inertial>
      <origin
        xyz="5.55111512312578E-17 0.0001765998131813 0"
        rpy="0 0 0" />
      <mass
        value="0.0487751853603893" />
      <inertia
        ixx="1.1945315130102E-05"
        ixy="6.30238478872746E-20"
        ixz="-2.93547733884741E-08"
        iyy="2.10139464635948E-05"
        iyz="-2.06191906923241E-21"
        izz="1.22437584607124E-05" />
    </inertial>
    <visual>
      <origin
        xyz="0 0 0"
        rpy="0 0 0" />
      <geometry>
        <mesh
          filename="package://car_total/meshes/right_back_wheel.STL" />
      </geometry>
      <material
        name="">
        <color
          rgba="1 1 1 1" />
      </material>
    </visual>
    <collision>
      <origin
        xyz="0 0 0"
        rpy="0 0 0" />
      <geometry>
        <mesh
          filename="package://car_total/meshes/right_back_wheel.STL" />
      </geometry>
    </collision>
  </link>
  <joint
    name="right_back_wheel_joint"
    type="continuous">
    <origin
      xyz="-0.156000000000004 -0.219000195879132 0"
      rpy="0 0 0" />
    <parent
      link="base_link" />
    <child
      link="right_back_wheel" />
    <axis
      xyz="0 -1 0" />
  </joint>
  <link
    name="left_ahead_arm">
    <inertial>
      <origin
        xyz="-8.51004324856075E-08 -0.00550753511779778 0.166867745732428"
        rpy="0 0 0" />
      <mass
        value="1.58786786548102" />
      <inertia
        ixx="0.0101203073694155"
        ixy="-2.47348248780182E-12"
        ixz="-6.46656692243147E-09"
        iyy="0.0114564870751773"
        iyz="8.66733028934315E-08"
        izz="0.00151495709722874" />
    </inertial>
    <visual>
      <origin
        xyz="0 0 0"
        rpy="0 0 0" />
      <geometry>
        <mesh
          filename="package://car_total/meshes/left_ahead_arm.STL" />
      </geometry>
      <material
        name="">
        <color
          rgba="0.752941176470588 0.752941176470588 0.752941176470588 1" />
      </material>
    </visual>
    <collision>
      <origin
        xyz="0 0 0"
        rpy="0 0 0" />
      <geometry>
        <mesh
          filename="package://car_total/meshes/left_ahead_arm.STL" />
      </geometry>
    </collision>
  </link>
  <joint
    name="left_ahead_arm_joint"
    type="revolute">
    <origin
      xyz="0.2776 0.241 0.0551"
      rpy="0 0 0" />
    <parent
      link="base_link" />
    <child
      link="left_ahead_arm" />
    <axis
      xyz="0 1 0" />
    <limit
      lower="-2.356"
      upper="2.356"
      effort="50"
      velocity="1.57" />
  </joint>
  <link
    name="left_back_arm">
    <inertial>
      <origin
        xyz="-8.51004331448024E-08 -0.00550753511779362 0.166867745732429"
        rpy="0 0 0" />
      <mass
        value="1.58786786548102" />
      <inertia
        ixx="0.0101203073694155"
        ixy="-2.47348281271855E-12"
        ixz="-6.46656686143657E-09"
        iyy="0.0114564870751773"
        iyz="8.66733026510441E-08"
        izz="0.00151495709722875" />
    </inertial>
    <visual>
      <origin
        xyz="0 0 0"
        rpy="0 0 0" />
      <geometry>
        <mesh
          filename="package://car_total/meshes/left_back_arm.STL" />
      </geometry>
      <material
        name="">
        <color
          rgba="0.752941176470588 0.752941176470588 0.752941176470588 1" />
      </material>
    </visual>
    <collision>
      <origin
        xyz="0 0 0"
        rpy="0 0 0" />
      <geometry>
        <mesh
          filename="package://car_total/meshes/left_back_arm.STL" />
      </geometry>
    </collision>
  </link>
  <joint
    name="left_back_arm_joint"
    type="revolute">
    <origin
      xyz="-0.2776 0.241 0.0551"
      rpy="0 0 0" />
    <parent
      link="base_link" />
    <child
      link="left_back_arm" />
    <axis
      xyz="0 1 0" />
    <limit
      lower="-2.356"
      upper="2.356"
      effort="50"
      velocity="1.57" />
  </joint>
  <link
    name="right_ahead_arm">
    <inertial>
      <origin
        xyz="8.51007760926947E-08 0.00550753511778909 0.166867745732428"
        rpy="0 0 0" />
      <mass
        value="1.58786786548102" />
      <inertia
        ixx="0.0101203073694156"
        ixy="-2.4734834015178E-12"
        ixz="6.46654918725069E-09"
        iyy="0.0114564870751773"
        iyz="-8.66733026516839E-08"
        izz="0.00151495709722884" />
    </inertial>
    <visual>
      <origin
        xyz="0 0 0"
        rpy="0 0 0" />
      <geometry>
        <mesh
          filename="package://car_total/meshes/right_ahead_arm.STL" />
      </geometry>
      <material
        name="">
        <color
          rgba="0.752941176470588 0.752941176470588 0.752941176470588 1" />
      </material>
    </visual>
    <collision>
      <origin
        xyz="0 0 0"
        rpy="0 0 0" />
      <geometry>
        <mesh
          filename="package://car_total/meshes/right_ahead_arm.STL" />
      </geometry>
    </collision>
  </link>
  <joint
    name="right_ahead_arm_joint"
    type="revolute">
    <origin
      xyz="0.2776 -0.241 0.0551"
      rpy="0 0 0" />
    <parent
      link="base_link" />
    <child
      link="right_ahead_arm" />
    <axis
      xyz="0 1 0" />
    <limit
      lower="-2.356"
      upper="2.356"
      effort="50"
      velocity="1.57" />
  </joint>
  <link
    name="right_back_arm">
    <inertial>
      <origin
        xyz="8.5100777647007E-08 0.0055075351177892 0.166867745732427"
        rpy="0 0 0" />
      <mass
        value="1.58786786548102" />
      <inertia
        ixx="0.0101203073694157"
        ixy="-2.47348333942772E-12"
        ixz="6.46654912680057E-09"
        iyy="0.0114564870751773"
        iyz="-8.66733026512871E-08"
        izz="0.0015149570972289" />
    </inertial>
    <visual>
      <origin
        xyz="0 0 0"
        rpy="0 0 0" />
      <geometry>
        <mesh
          filename="package://car_total/meshes/right_back_arm.STL" />
      </geometry>
      <material
        name="">
        <color
          rgba="0.752941176470588 0.752941176470588 0.752941176470588 1" />
      </material>
    </visual>
    <collision>
      <origin
        xyz="0 0 0"
        rpy="0 0 0" />
      <geometry>
        <mesh
          filename="package://car_total/meshes/right_back_arm.STL" />
      </geometry>
    </collision>
  </link>
  <joint
    name="right_back_arm_joint"
    type="revolute">
    <origin
      xyz="-0.2776 -0.241 0.0551"
      rpy="0 0 0" />
    <parent
      link="base_link" />
    <child
      link="right_back_arm" />
    <axis
      xyz="0 1 0" />
    <limit
      lower="-2.356"
      upper="2.356"
      effort="50"
      velocity="1.57" />
  </joint>
  <link
    name="big_course_part">
    <inertial>
      <origin
        xyz="1.74756242143914E-07 0.000840655594496878 -0.000626644403587368"
        rpy="0 0 0" />
      <mass
        value="4.058247002138" />
      <inertia
        ixx="0.00215393279764294"
        ixy="7.58591199427514E-08"
        ixz="-3.93372022303762E-08"
        iyy="0.00241219360465986"
        iyz="2.17404141773737E-07"
        izz="0.00317731381306234" />
    </inertial>
    <visual>
      <origin
        xyz="0 0 0"
        rpy="0 0 0" />
      <geometry>
        <mesh
          filename="package://car_total/meshes/big_course_part.STL" />
      </geometry>
      <material
        name="">
        <color
          rgba="0.898039215686275 0.917647058823529 0.929411764705882 1" />
      </material>
    </visual>
    <collision>
      <origin
        xyz="0 0 0"
        rpy="0 0 0" />
      <geometry>
        <mesh
          filename="package://car_total/meshes/big_course_part.STL" />
      </geometry>
    </collision>
  </link>
  <joint
    name="big_course_joint"
    type="revolute">
    <origin
      xyz="-0.12025 0.0010002 0.19985"
      rpy="0 0 0" />
    <parent
      link="base_link" />
    <child
      link="big_course_part" />
    <axis
      xyz="0 0 1" />
    <limit
      lower="-1.57"
      upper="1.57"
      effort="66"
      velocity="1.57" />
  </joint>
  <link
    name="big_pitch_part">
    <inertial>
      <origin
        xyz="0.223602368000298 0.00351787542231884 0.157408489138648"
        rpy="0 0 0" />
      <mass
        value="1.11922785774065" />
      <inertia
        ixx="0.00206915287958648"
        ixy="1.66867634828652E-07"
        ixz="-0.00253507622801385"
        iyy="0.00572908953033018"
        iyz="2.83510380604844E-07"
        izz="0.00391352949035926" />
    </inertial>
    <visual>
      <origin
        xyz="0 0 0"
        rpy="0 0 0" />
      <geometry>
        <mesh
          filename="package://car_total/meshes/big_pitch_part.STL" />
      </geometry>
      <material
        name="">
        <color
          rgba="0.898039215686275 0.917647058823529 0.929411764705882 1" />
      </material>
    </visual>
    <collision>
      <origin
        xyz="0 0 0"
        rpy="0 0 0" />
      <geometry>
        <mesh
          filename="package://car_total/meshes/big_pitch_part.STL" />
      </geometry>
    </collision>
  </link>
  <joint
    name="big_pitch_joint"
    type="revolute">
    <origin
      xyz="0 -0.00320000000000144 0.0614876897975586"
      rpy="0 0 0" />
    <parent
      link="big_course_part" />
    <child
      link="big_pitch_part" />
    <axis
      xyz="0 1 0" />
    <limit
      lower="-2.531"
      upper="0"
      effort="66"
      velocity="1.57" />
  </joint>
  <link
    name="small_pitch_part">
    <inertial>
      <origin
        xyz="-0.151760367500101 -0.00702848793080098 -0.0547270044732647"
        rpy="0 0 0" />
      <mass
        value="1.16129887078162" />
      <inertia
        ixx="0.000918508848044831"
        ixy="-4.47630851648167E-06"
        ixz="-0.000572476456890627"
        iyy="0.00212433704129479"
        iyz="-1.44540267941281E-06"
        izz="0.00228319496367273" />
    </inertial>
    <visual>
      <origin
        xyz="0 0 0"
        rpy="0 0 0" />
      <geometry>
        <mesh
          filename="package://car_total/meshes/small_pitch_part.STL" />
      </geometry>
      <material
        name="">
        <color
          rgba="0.898039215686275 0.917647058823529 0.929411764705882 1" />
      </material>
    </visual>
    <collision>
      <origin
        xyz="0 0 0"
        rpy="0 0 0" />
      <geometry>
        <mesh
          filename="package://car_total/meshes/small_pitch_part.STL" />
      </geometry>
    </collision>
  </link>
  <joint
    name="small_pitch_joint"
    type="revolute">
    <origin
      xyz="0.42211 0.0098 0.29556"
      rpy="0 0 0" />
    <parent
      link="big_pitch_part" />
    <child
      link="small_pitch_part" />
    <axis
      xyz="0 1 0" />
    <limit
      lower="-3.14"
      upper="3.14"
      effort="18"
      velocity="1.57" />
  </joint>
  <link
    name="hands_pitch_part">
    <inertial>
      <origin
        xyz="-0.0104504695371929 -0.0245556138833306 -0.00380373964260527"
        rpy="0 0 0" />
      <mass
        value="0.198490694575794" />
      <inertia
        ixx="4.28672080428007E-05"
        ixy="-1.98605745647437E-06"
        ixz="-8.74224750649097E-06"
        iyy="6.48873353986136E-05"
        iyz="-1.14209401186416E-06"
        izz="6.37056808544144E-05" />
    </inertial>
    <visual>
      <origin
        xyz="0 0 0"
        rpy="0 0 0" />
      <geometry>
        <mesh
          filename="package://car_total/meshes/hands_pitch_part.STL" />
      </geometry>
      <material
        name="">
        <color
          rgba="0.898039215686275 0.917647058823529 0.929411764705882 1" />
      </material>
    </visual>
    <collision>
      <origin
        xyz="0 0 0"
        rpy="0 0 0" />
      <geometry>
        <mesh
          filename="package://car_total/meshes/hands_pitch_part.STL" />
      </geometry>
    </collision>
  </link>
  <joint
    name="hands_pitch_joint"
    type="revolute">
    <origin
      xyz="-0.40971 -0.0451 -0.14912"
      rpy="0 0 0" />
    <parent
      link="small_pitch_part" />
    <child
      link="hands_pitch_part" />
    <axis
      xyz="0 1 0" />
    <limit
      lower="-1.57"
      upper="1.57"
      effort="6"
      velocity="1.57" />
  </joint>
  <link
    name="hands_roll_part">
    <inertial>
      <origin
        xyz="-0.0184219700917893 -7.25603639083194E-08 -0.0186529175454785"
        rpy="0 0 0" />
      <mass
        value="0.206028609980917" />
      <inertia
        ixx="6.76301152596878E-05"
        ixy="3.71700787949823E-07"
        ixz="6.7746262152741E-06"
        iyy="7.03217071271944E-05"
        iyz="1.35721638011442E-07"
        izz="4.25774678272544E-05" />
    </inertial>
    <visual>
      <origin
        xyz="0 0 0"
        rpy="0 0 0" />
      <geometry>
        <mesh
          filename="package://car_total/meshes/hands_roll_part.STL" />
      </geometry>
      <material
        name="">
        <color
          rgba="0.898039215686275 0.917647058823529 0.929411764705882 1" />
      </material>
    </visual>
    <collision>
      <origin
        xyz="0 0 0"
        rpy="0 0 0" />
      <geometry>
        <mesh
          filename="package://car_total/meshes/hands_roll_part.STL" />
      </geometry>
    </collision>
  </link>
  <joint
    name="hands_roll_joint"
    type="revolute">
    <origin
      xyz="-0.046515 -0.0265 -0.01693"
      rpy="0 0 0" />
    <parent
      link="hands_pitch_part" />
    <child
      link="hands_roll_part" />
    <axis
      xyz="0.93969 0 0.34202" />
    <limit
      lower="-2.356"
      upper="2.356"
      effort="6"
      velocity="1.57" />
  </joint>
  <link
    name="handshands_course_part">
    <inertial>
      <origin
        xyz="-0.0265518945654351 -7.45931094670027E-16 -0.00966409928516149"
        rpy="0 0 0" />
      <mass
        value="0.100681278037507" />
      <inertia
        ixx="3.6285533122064E-05"
        ixy="2.45657466640692E-18"
        ixz="-1.873867431146E-05"
        iyy="6.87920373492824E-05"
        iyz="1.49586441413461E-18"
        izz="8.09492979845232E-05" />
    </inertial>
    <visual>
      <origin
        xyz="0 0 0"
        rpy="0 0 0" />
      <geometry>
        <mesh
          filename="package://car_total/meshes/handshands_course_part.STL" />
      </geometry>
      <material
        name="">
        <color
          rgba="1 1 1 1" />
      </material>
    </visual>
    <collision>
      <origin
        xyz="0 0 0"
        rpy="0 0 0" />
      <geometry>
        <mesh
          filename="package://car_total/meshes/handshands_course_part.STL" />
      </geometry>
    </collision>
  </link>
  <joint
    name="hands_course_joint"
    type="revolute">
    <origin
      xyz="-0.0045517 0 -0.064975"
      rpy="0 0 0" />
    <parent
      link="hands_roll_part" />
    <child
      link="handshands_course_part" />
    <axis
      xyz="0.34202 0 -0.93969" />
    <limit
      lower="-1.57"
      upper="1.57"
      effort="6"
      velocity="1.57" />
  </joint>
  <link
    name="lidar">
    <inertial>
      <origin
        xyz="-1.62370117351429E-15 3.33066907387547E-16 -4.44089209850063E-16"
        rpy="0 0 0" />
      <mass
        value="0.742920987579563" />
      <inertia
        ixx="0.000937798449134027"
        ixy="1.03077101557214E-34"
        ixz="4.61708918612271E-19"
        iyy="0.000937798449134027"
        iyz="2.78475796235466E-20"
        izz="0.0010632127983498" />
    </inertial>
    <visual>
      <origin
        xyz="0 0 0"
        rpy="0 0 0" />
      <geometry>
        <mesh
          filename="package://car_total/meshes/lidar.STL" />
      </geometry>
      <material
        name="">
        <color
          rgba="1 1 1 1" />
      </material>
    </visual>
    <collision>
      <origin
        xyz="0 0 0"
        rpy="0 0 0" />
      <geometry>
        <mesh
          filename="package://car_total/meshes/lidar.STL" />
      </geometry>
    </collision>
  </link>
  <joint
    name="lidar_joint"
    type="fixed">
    <origin
      xyz="0.1555 -0.0010002 0.3007"
      rpy="0 0 0" />
    <parent
      link="base_link" />
    <child
      link="lidar" />
    <axis
      xyz="0 0 0" />
  </joint>
  <link
    name="camera">
    <inertial>
      <origin
        xyz="-0.00422507049806128 0.00323775103650949 -0.00209736042516043"
        rpy="0 0 0" />
      <mass
        value="0.0491654266514405" />
      <inertia
        ixx="2.7939284365415E-05"
        ixy="-4.34509658882138E-07"
        ixz="7.70024903303845E-09"
        iyy="3.41762421577895E-06"
        iyz="2.15842945495298E-09"
        izz="2.71851885152033E-05" />
    </inertial>
    <visual>
      <origin
        xyz="0 0 0"
        rpy="0 0 0" />
      <geometry>
        <mesh
          filename="package://car_total/meshes/camera.STL" />
      </geometry>
      <material
        name="">
        <color
          rgba="1 1 1 1" />
      </material>
    </visual>
    <collision>
      <origin
        xyz="0 0 0"
        rpy="0 0 0" />
      <geometry>
        <mesh
          filename="package://car_total/meshes/camera.STL" />
      </geometry>
    </collision>
  </link>
  <joint
    name="camera_joint"
    type="fixed">
    <origin
      xyz="0.254895203624053 -0.00376119017118451 0.228826235475407"
      rpy="0 0 0" />
    <parent
      link="base_link" />
    <child
      link="camera" />
    <axis
      xyz="0 0 0" />
  </joint>
</robot>